Workbook

Sheet 說明
A1: AI 產業鏈研究資料庫
A2: 基準日 2026-10-05。搭配《AI 產業鏈投資查證手冊》2.2.1 版使用：方法在手冊，數字在這裡。
A3: 這不是投資建議。所有股價與估值都會過期，使用前必須重抓。
A5: 怎麼用
A6: 黃底儲存格＝尚未填寫，需要你或下次更新時補上。
A7: 藍字＝手動輸入的數字或日期；黑字＝公式或文字。
A8: 每張表第一列的資料列都是真實資料，可當填寫格式的範例。
A9: 新財報或月營收公布時：在 Quarterly_Results 或 TW_Monthly 新增一列，再到 Evidence_Ledger 補一筆來源，最後更新 Event_Log 的結果欄。
A10: 驗證狀態只有四種：已開原文／僅摘要／轉述／未查。「僅摘要」代表只看過搜尋回傳的頁面摘錄，數字可能漏掉限定詞。
A12: 各分頁
A13: Companies | B13: 公司主檔：產業位置、成熟度分層、歸因等級
A14: Quarterly_Results | B14: 季度財報：一季一列
A15: TW_Monthly | B15: 台股月營收：一月一列
A16: Valuation | B16: 估值快照：全部待填，每次重抓
A17: Industry_KPIs | B17: 產業指標與研究機構預估
A18: Event_Log | B18: 事件日曆與預期差紀錄
A19: Evidence_Ledger | B19: 證據總帳：每個主張一列
A20: Risk_Factors | B20: 共同風險因子（主觀評級）
A21: Stress_Test | B21: 壓力測試計算（填黃格）
A22: Predictions | B22: 預測成績單
A23: Change_Log | B23: 更正紀錄
A25: 證據總帳統計
A26: 主張總數 | B26: =COUNTA(Evidence_Ledger!A2:A500) -> 83
A27: 已開原文 | B27: =COUNTIF(Evidence_Ledger!J2:J500,"已開原文") -> 17
A28: 僅摘要 | B28: =COUNTIF(Evidence_Ledger!J2:J500,"僅摘要") -> 55
A29: 轉述 | B29: =COUNTIF(Evidence_Ledger!J2:J500,"轉述") -> 1
A30: 未查 | B30: =COUNTIF(Evidence_Ledger!J2:J500,"未查") -> 10
A32: 單位約定
A33: 本試算表的百分比儲存格內部值是小數（顯示 379% 的格子內部是 3.79）。搬到執行紀錄 JSON 時要乘以 100，寫成 379。公司代號一律用 Companies 分頁的標準代號（台積電用 TSM，不用 2330）。

Sheet Companies
A1: 代號 | B1: 公司 | C1: 市場 | D1: 產業位置 | E1: 成熟度分層 | F1: 歸因等級（A–D） | G1: 會計年度結束 | H1: 備註
A2: MU | B2: 美光 | C2: 美股 | D2: 記憶體 | E2: 第一層 | F2: A | G2: 8 月（會計年度）
A3: AVGO | B3: Broadcom | C3: 美股 | D3: 客製 AI 晶片與網通 | E3: 第一層 | F3: A | G3: 10 月底／11 月初 | H3: 前五大終端客戶佔 Q3 營收 55%
A4: TSM | B4: 台積電 2330 | C4: 台股 | D4: 晶圓代工與先進封裝 | E4: 第一層 | F4: 未評 | G4: 12 月
A5: MRVL | B5: Marvell | C5: 美股 | D5: 資料中心晶片與光連接 | E5: 第一層 | F5: A | G5: 1 月底 | H5: 揭露的是整個資料中心部門，不全是 AI
A6: LITE | B6: Lumentum | C6: 美股 | D6: 光元件與系統 | E6: 第一層 | F6: 未評 | G6: 6 月
A7: COHR | B7: Coherent | C7: 美股 | D7: 光通訊與光電 | E7: 第一層 | F7: 未評 | G7: 6 月
A8: ANET | B8: Arista | C8: 美股 | D8: AI 乙太網路 | E8: 第一層 | F8: 未評 | G8: 12 月 | H8: 97 億採購承諾是對供應商，不是客戶訂單
A9: VRT | B9: Vertiv | C9: 美股 | D9: 電力與散熱 | E9: 第一層 | F9: 未評 | G9: 12 月
A10: ETN | B10: Eaton | C10: 美股 | D10: 電力管理 | E10: 第一層 | F10: 未評 | G10: 12 月 | H10: 終端較分散
A11: APH | B11: Amphenol | C11: 美股 | D11: 連接器與線纜 | E11: 第一層 | F11: 未評 | G11: 12 月
A12: 6857 | B12: Advantest | C12: 日股 | D12: 半導體測試 | E12: 第一層 | F12: 未評 | G12: 3 月
A13: PANW | B13: Palo Alto Networks | C13: 美股 | D13: 資安 | E13: 第一層 | F13: 未評 | G13: 7 月
A14: GEV | B14: GE Vernova | C14: 美股 | D14: 發電與電網 | E14: 第一層 | F14: 未評 | G14: 12 月
A15: 2408 | B15: 南亞科 | C15: 台股 | D15: 記憶體 | E15: 第一層 | F15: 未評 | G15: 12 月
A16: 2344 | B16: 華邦電 | C16: 台股 | D16: 記憶體 | E16: 第一層 | F16: 未評 | G16: 12 月
A17: 3081 | B17: 聯亞 | C17: 台股 | D17: 磷化銦磊晶與雷射 | E17: 第一層 | F17: B | G17: 12 月 | H17: 公司稱矽光子需求強，未給分項數字
A18: 6274 | B18: 台燿 | C18: 台股 | D18: 高速銅箔基板 | E18: 第一層 | F18: C | G18: 12 月 | H18: 不是光通訊股
A19: 3017 | B19: 奇鋐 | C19: 台股 | D19: 散熱 | E19: 第一層 | F19: C | G19: 12 月
A20: 3324 | B20: 雙鴻 | C20: 台股 | D20: 散熱 | E20: 第一層 | F20: B | G20: 12 月 | H20: 公司稱液冷佔營收過半
A21: 3363 | B21: 上詮 | C21: 台股 | D21: 光纖與 FAU | E21: 第二層 | F21: D | G21: 12 月 | H21: 上半年每股虧損 1.18 元
A22: 3008 | B22: 大立光 | C22: 台股 | D22: 光學鏡頭；FAU 為選擇權 | E22: 第三層 | F22: D | G22: 12 月 | H22: FAU 最快 2027 年中（未查原文）
A23: 9069 | B23: センコーグループHD | C23: 日股 | D23: 物流 | E23: 不適用 | F23: 不適用 | G23: 3 月 | H23: 與光通訊 SENKO 無關，勿混淆

Sheet Quarterly_Results
A1: 代號 | B1: 期間 | C1: 期末日 | D1: 營收 | E1: 單位 | F1: 年增 | G1: 季增 | H1: 有機成長 | I1: 毛利率 | J1: 財測 | K1: 但書 | L1: 驗證狀態 | M1: 來源
A2: MU | B2: FY26 Q4 | C2: 46268 | D2: 542.3 | E2: 億美元 | F2: 3.79 | G2: 0.31 | I2: 0.87 | J2: 下季 615±15 億；毛利率約 86.25% | K2: 位元出貨僅季增中個位數；毛利率財測低於市場預期 86.7% | L2: 僅摘要 | M2: https://news.cnyes.com/news/id/6619198
A3: AVGO | B3: FY26 Q3 | C3: 46236 | D3: 296 | E3: 億美元 | F3: 0.86 | J3: Q4 營收約 348 億；AI 半導體 217 億 | K3: AI 半導體 167 億年增 221%；前五大終端客戶 55%、單一經銷商 50% | L3: 已開原文 | M3: https://investors.broadcom.com/static-files/96641754-401f-4090-a4ab-210728c83a28
A4: MRVL | B4: FY27 Q2 | C4: 46235 | D4: 27.39 | E4: 億美元 | F4: 0.37 | I4: 0.531 | J4: 投資人日 10/6 更新 | K4: 資料中心年增 46%；非 GAAP EPS 0.94、GAAP 0.33；毛利率為 GAAP | L4: 僅摘要 | M4: https://www.sec.gov/Archives/edgar/data/0001835632/000183563226000022/q227_8kx812026ex-991.htm
A5: LITE | B5: FY26 Q4 | C5: 46200 | D5: 10.063 | E5: 億美元 | F5: 1.093 | G5: 0.245 | I5: 0.474 | J5: 下季 12.25–12.75 億 | K5: GAAP 淨損 72 億，來自可轉債轉換的一次性非現金損失；非 GAAP 毛利率 50.4% | L5: 僅摘要 | M5: https://investor.lumentum.com/financial-news-releases/news-details/2026/Lumentum-Announces-Fourth-Quarter-and-Full-Fiscal-Year-2026-Results/default.aspx
A6: COHR | B6: FY26 Q4 | C6: 46203 | D6: 20.5 | E6: 億美元 | F6: 0.34 | I6: 0.385 | K6: 擬制年增 42%；非 GAAP 毛利率 40.2% | L6: 僅摘要 | M6: https://www.coherent.com/news/press-releases/fourth-quarter-and-fiscal-year-2026-results
A7: ANET | B7: 2026 Q2 | C7: 46203 | D7: 30.36 | E7: 億美元 | F7: 0.377 | G7: 0.121 | J7: 全年約 126 億（成長 40%）；Q3 約 33 億 | K7: 97 億不可取消採購承諾（94 億 12 個月內收貨）；未來將認列營收 84 億 | L7: 已開原文 | M7: https://www.sec.gov/Archives/edgar/data/1596532/000159653226000175/anet-20260630.htm
A8: VRT | B8: 2026 Q2 | C8: 46203 | D8: 32.74 | E8: 億美元 | F8: 0.24 | H8: 0.18 | J8: 全年有機成長 30–32% | K8: 歐非中東有機衰退 2%；併購貢獻 5 個百分點 | L8: 僅摘要 | M8: https://investors.vertiv.com/news/news-details/2026/Vertiv-Reports-Strong-Second-Quarter-2026-with-Diluted-EPS-Growth-of-53-Adjusted-Diluted-EPS-Growth-of-60-Raises-Full-Year-2026-Guidance-Across-All-Key-Metrics/default.aspx
A9: ETN | B9: 2026 Q2 | C9: 46203 | D9: 85 | E9: 億美元 | F9: 0.21 | H9: 0.14 | J9: 上修全年有機成長 | K9: 訂單增 41% 是 12 個月滾動；美洲電氣利益率 29.5%→27.5% | L9: 僅摘要 | M9: https://www.businesswire.com/news/home/20260730561562/en/Eaton-Reports-Record-Second-Quarter-2026-Results-with-Strong-Organic-Growth-Accelerating-Orders-and-Backlog-and-Raises-Organic-Growth-Guidance
A10: APH | B10: 2026 Q2 | C10: 46203 | D10: 87.58 | E10: 億美元 | F10: 0.55 | H10: 0.3 | J10: Q3 93–94 億 | K10: 併購貢獻 24 個百分點；訂單 107 億、訂單出貨比 1.23 | L10: 僅摘要 | M10: https://www.sec.gov/Archives/edgar/data/0000820313/000110465926087904/aph-20260729xex99d1.htm
A11: 6857 | B11: FY26 Q1 | C11: 46203 | D11: 3675 | E11: 億日圓 | F11: 0.393 | I11: 0.695 | J11: 全年營業利益 8,460 億日圓 | K11: 淨利含約 447 億日圓金融收益 | L11: 僅摘要 | M11: https://www.advantest.com/document/en/investors/ir-library/result/E_FR_FY2026_1Q.pdf
A12: PANW | B12: FY26 Q4 | C12: 46234 | D12: 34.1 | E12: 億美元 | F12: 0.34 | I12: 0.748 | J12: 新年度營收 141–142 億（成長 23–24%） | K12: 當季 GAAP 淨損 2.82 億；成長含併購 | L12: 僅摘要 | M12: https://investors.paloaltonetworks.com/news-releases/news-release-details/palo-alto-networks-reports-fiscal-fourth-quarter-and-fiscal-10
A13: GEV | B13: 2026 Q2 | C13: 46203 | D13: 111 | E13: 億美元 | F13: 0.22 | H13: 0.12 | J13: 上修全年財測 | K13: 訂單 242 億有機增 88%；風電訂單有機衰退 40%；淨利率 5.8% | L13: 僅摘要 | M13: https://www.gevernova.com/sites/default/files/gev_webcast_pressrelease_07222026.pdf

Sheet TW_Monthly
A1: 代號 | B1: 公司 | C1: 月份 | D1: 營收（億元） | E1: 年增 | F1: 月增 | G1: 累計年增 | H1: 備註 | I1: 驗證狀態 | J1: 來源
A2: 2330 | B2: 台積電 | C2: 2026-08 | D2: 5148.05 | E2: 0.533 | F2: 0.101 | G2: 0.393 | H2: 公告日股價 2,450 元（快變） | I2: 僅摘要 | J2: https://news.cnyes.com/news/id/6603050
A3: 2408 | B3: 南亞科 | C3: 2026-08 | D3: 446.9 | E3: 5.609 | F3: 0.019 | G3: 6.382 | H3: 新合約 7 月生效，月增停滯屬階梯式調價 | I3: 僅摘要 | J3: https://news.ustv.com.tw/newsdetail/20260902A001020
A4: 2344 | B4: 華邦電 | C4: 2026-08 | D4: 273.08 | E4: 2.894 | F4: 0.02 | G4: 1.774 | I4: 僅摘要 | J4: https://udn.com/news/story/7252/9741093
A5: 3081 | B5: 聯亞 | C5: 2026-08 | D5: 5.2 | E5: 1.809 | F5: 0.038 | G5: 1.29 | H5: 公告日股價 3,170 元（快變） | I5: 僅摘要 | J5: https://news.cnyes.com/news/id/6597602
A6: 6274 | B6: 台燿 | C6: 2026-08 | D6: 59.15 | E6: 1.325 | F6: 0.001 | G6: 0.97 | H6: 月增幾乎為零 | I6: 僅摘要 | J6: https://m.cnyes.com/news/id/6597745
A7: 3017 | B7: 奇鋐 | C7: 2026-08 | D7: 194.81 | E7: 0.543 | F7: 0.048 | G7: 0.761 | I7: 僅摘要 | J7: https://news.cnyes.com/news/id/6600144
A8: 3324 | B8: 雙鴻 | C8: 2026-08 | D8: 31.41 | E8: 0.672 | F8: -0.166 | G8: 0.81 | H8: 被列處置股 | I8: 僅摘要 | J8: https://www.ctee.com.tw/news/20260908701262-430502
A9: 3363 | B9: 上詮 | C9: 2026-08 | D9: 2.04 | E9: 0.132 | F9: 0.196 | G9: -0.106 | H9: FAU 第三季僅微量貢獻 | I9: 僅摘要 | J9: https://www.chinatimes.com/realtimenews/20260905002223-260410
A10: 2330 | B10: 台積電 | C10: 2026-09 | H10: 10/8 13:30 公布；高於 4,448 億即達 Q3 財測低標 | I10: 未查 | J10: https://investor.tsmc.com/english/financial-calendar

Sheet Valuation
A1: 全部屬於快變資料，每次判斷前重抓。填入股價與每股盈餘後，本益比自動計算。
A2: 代號 | B2: 公司 | C2: 抓取日 | D2: 股價 | E2: 未來 12 個月每股盈餘 | F2: 本益比（公式） | G2: 歷史分位 | H2: 備註
A3: MU | B3: 美光 | C3: 46294 | D3: 1070 | F3: =IF(AND(ISNUMBER(D3),ISNUMBER(E3),E3<>0),D3/E3,"") | H3: 股價為財報前新聞數字，已過期；曾以下季財測年化回推約 6–7 倍
A4: AVGO | B4: Broadcom | F4: =IF(AND(ISNUMBER(D4),ISNUMBER(E4),E4<>0),D4/E4,"")
A5: TSM | B5: 台積電 2330 | F5: =IF(AND(ISNUMBER(D5),ISNUMBER(E5),E5<>0),D5/E5,"")
A6: MRVL | B6: Marvell | F6: =IF(AND(ISNUMBER(D6),ISNUMBER(E6),E6<>0),D6/E6,"")
A7: LITE | B7: Lumentum | F7: =IF(AND(ISNUMBER(D7),ISNUMBER(E7),E7<>0),D7/E7,"")
A8: COHR | B8: Coherent | F8: =IF(AND(ISNUMBER(D8),ISNUMBER(E8),E8<>0),D8/E8,"")
A9: ANET | B9: Arista | F9: =IF(AND(ISNUMBER(D9),ISNUMBER(E9),E9<>0),D9/E9,"")
A10: VRT | B10: Vertiv | F10: =IF(AND(ISNUMBER(D10),ISNUMBER(E10),E10<>0),D10/E10,"")
A11: ETN | B11: Eaton | F11: =IF(AND(ISNUMBER(D11),ISNUMBER(E11),E11<>0),D11/E11,"")
A12: APH | B12: Amphenol | F12: =IF(AND(ISNUMBER(D12),ISNUMBER(E12),E12<>0),D12/E12,"")
A13: 6857 | B13: Advantest | F13: =IF(AND(ISNUMBER(D13),ISNUMBER(E13),E13<>0),D13/E13,"")
A14: PANW | B14: Palo Alto Networks | F14: =IF(AND(ISNUMBER(D14),ISNUMBER(E14),E14<>0),D14/E14,"")
A15: GEV | B15: GE Vernova | F15: =IF(AND(ISNUMBER(D15),ISNUMBER(E15),E15<>0),D15/E15,"")
... A23: 3008 | B23: 大立光 | F23: =IF(AND(ISNUMBER(D23),ISNUMBER(E23),E23<>0),D23/E23,"")

Sheet Industry_KPIs
A1: 主線 | B1: 指標 | C1: 資料日期 | D1: 數值 | E1: 主張類型 | F1: 但書 | G1: 來源
A2: 總經 | B2: 聯邦基金利率目標區間 | C2: 46281 | D2: 3.75%–4.00% | E2: 實績 | F2: 12:0 通過升一碼 | G2: https://www.foxbusiness.com/economy/federal-reserve-interest-rate-decision-september-16-2026
A3: 總經 | B3: 點陣圖 2026 年底中位數 | C3: 46281 | D3: 4.1%（18 人中 12 人在 4.125%） | E3: 第三方估計 | F3: 與會者預測，不是承諾 | G3: https://www.federalreserve.gov/monetarypolicy/fomcprojtabl20260916.htm
A4: 總經 | B4: 9 月非農新增／失業率 | C4: 46297 | D4: 2.9 萬人／4.2% | E4: 實績 | G4: https://www.bls.gov/news.release/empsit.htm
A5: 記憶體 | B5: DRAM+NAND 佔雲端業者資本支出 | C5: 46259 | D5: 2026 年 47%、2027 年 68% | E5: 第三方估計 | F5: TrendForce 模型，非客戶預算 | G5: https://www.trendforce.com/presscenter/news/20260825-13198.html
A6: 記憶體 | B6: 2027 年 HBM 混合均價年增 | C6: 46294 | D6: 121% | E6: 第三方估計 | G6: https://www.trendforce.com/presscenter/news/20260929-13255.html
A7: 記憶體 | B7: 輝達 Rubin Ultra 記憶體配置 | C7: 46238 | D7: 評估降到 8 層、192GB | E7: 第三方估計 | F7: 主因是供給不足與驗證不確定，不是需求轉弱 | G7: https://aiweekly.co/alerts/nvidia-tests-lower-memory-rubin-ultra-variants-amid-hbm-squeeze
A8: 儲存 | B8: 企業級 SSD 前五大營收 | C8: 46266 | D8: 2026Q2 375.9 億美元，季增 103.6% | E8: 第三方估計 | G8: https://www.trendforce.com/presscenter/news/20260901-13210.html
A9: 被動元件 | B9: 三星電機第四季調價 | C9: 46261 | D9: X5R 漲 25–30%、X6S 漲 10–20% | E9: 第三方估計 | F9: 消費級現貨價 9 月已回落 | G9: https://www.trendforce.com/presscenter/news/20260827-13202.html
A10: 運算 | B10: 代理式 AI 的 CPU 對 GPU 比例 | C10: 46136 | D10: 由 1:4–1:8 走向 1:1–1:2 | E10: 第三方估計 | G10: https://insights.trendforce.com/p/agentic-ai-cpu-gpu
A11: 應用 | B11: Meta Muse 美國下載量 | C11: 46295 | D11: 22 天約 500 萬 | E11: 第三方估計 | F11: Sensor Tower 估計；Meta 未公布 | G11: https://www.forbes.com/sites/maryroeloffs/2026/09/30/metas-muse-ai-assistant-hits-5-million-downloads-outpacing-growth-of-chatgpt-grok-and-claude/

Sheet Event_Log
A1: 日期 | B1: 距基準日天數 | C1: 事件 | D1: 主張類型 | E1: 事前共識 | F1: 實際結果 | G1: 個股 1 日漲跌 | H1: 同類指數 1 日漲跌 | I1: 超額漲跌（公式） | J1: 觀察重點／結論 | K1: 來源
A2: 46295 | B2: =A2-DATE(2026,10,5) -> -5 | C2: 美光 FY26 Q4 財報 | D2: 實績 | E2: 營收共識 510.7 億 | F2: 營收 542.3 億；財測 615 億 | I2: =IF(AND(ISNUMBER(G2),ISNUMBER(H2)),G2-H2,"") | J2: 結果優於共識但股價無反應 | K2: https://news.cnyes.com/news/id/6619198
A3: 46301 | B3: =A3-DATE(2026,10,5) -> 1 | C3: Marvell 投資人日（美東 9:00 直播） | D3: 實績 | I3: =IF(AND(ISNUMBER(G3),ISNUMBER(H3)),G3-H3,"") | J3: 長期營收目標是否上修；跌幅是否大於半導體指數 | K3: https://www.marvell.com/company/events.html
A4: 46303 | B4: =A4-DATE(2026,10,5) -> 3 | C4: 台積電 9 月營收（13:30） | D4: 實績 | I4: =IF(AND(ISNUMBER(G4),ISNUMBER(H4)),G4-H4,"") | J4: 是否高於 4,448 億 | K4: https://investor.tsmc.com/english/financial-calendar
A5: 46305 | B5: =A5-DATE(2026,10,5) -> 5 | C5: 台股 9 月營收截止 | D5: 實績 | I5: =IF(AND(ISNUMBER(G5),ISNUMBER(H5)),G5-H5,"") | J5: 聯亞、全新、台燿、奇鋐、雙鴻、上詮是否延續
A6: 46308 | B6: =A6-DATE(2026,10,5) -> 8 | C6: 蘋果智慧家居發表 | D6: 傳聞 | I6: =IF(AND(ISNUMBER(G6),ISNUMBER(H6)),G6-H6,"") | J6: 是否真的發表 | K6: https://www.iclarified.com/102501/apple-targets-october-13-for-smart-home-hub-new-homepod-mini-and-apple-tv-gurman
A7: 46310 | B7: =A7-DATE(2026,10,5) -> 10 | C7: 台積電 Q3 法說（14:00） | D7: 實績 | I7: =IF(AND(ISNUMBER(G7),ISNUMBER(H7)),G7-H7,"") | J7: 資本支出與 2027 年展望 | K7: https://investor.tsmc.com/english/financial-calendar
A8: 46311 | B8: =A8-DATE(2026,10,5) -> 11 | C8: iPhone Duo 預購 | D8: 實績 | I8: =IF(AND(ISNUMBER(G8),ISNUMBER(H8)),G8-H8,"") | J8: 預購數字是否公布 | K8: https://www.apple.com/newsroom/2026/09/apple-unveils-iphone-duo/
A9: 46323 | B9: =A9-DATE(2026,10,5) -> 23 | C9: 聯準會決議（10/27–28） | D9: 實績 | I9: =IF(AND(ISNUMBER(G9),ISNUMBER(H9)),G9-H9,"") | J9: 是否暫停升息
A10: 46325 | B10: =A10-DATE(2026,10,5) -> 25 | C10: 四大雲端業者財報週結束 | D10: 實績 | I10: =IF(AND(ISNUMBER(G10),ISNUMBER(H10)),G10-H10,"") | J10: 合計 2027 年資本支出方向
A11: 46336 | B11: =A11-DATE(2026,10,5) -> 36 | C11: 台積電與台股 10 月營收 | D11: 實績 | I11: =IF(AND(ISNUMBER(G11),ISNUMBER(H11)),G11-H11,"") | J11: 南亞科、華邦電是否再上一階 | K11: https://investor.tsmc.com/english/financial-calendar

Sheet Evidence_Ledger
A1: 主張編號 | B1: 對象 | C1: 指標 | D1: 期間 | E1: 數值 | F1: 單位 | G1: 主張類型 | H1: 來源等級 | I1: — | J1: 驗證狀態 | K1: 來源日期 | L1: 查閱日期 | M1: 但書 | N1: 更新觸發 | O1: 來源網址
A2: =TEXT(ROW()-1,"C-000") -> C-001 | B2: MU | C2: 營收 | D2: FY26 Q4 | E2: 542.3 | F2: 億美元 | G2: 實績 | H2: 1 | J2: 僅摘要 | K2: 46268 | L2: 46300 | M2: 位元出貨僅季增中個位數；毛利率財測低於市場預期 86.7% | N2: 下一季財報 | O2: https://news.cnyes.com/news/id/6619198
A3: =TEXT(ROW()-1,"C-000") -> C-002 | B3: MU | C3: 營收年增 | D3: FY26 Q4 | E3: 3.79 | F3: 比率 | G3: 實績 | H3: 1 | J3: 僅摘要 | K3: 46268 | L3: 46300 | N3: 下一季財報 | O3: https://news.cnyes.com/news/id/6619198
A4: =TEXT(ROW()-1,"C-000") -> C-003 | B4: MU | C4: 財測 | D4: FY26 Q4 | E4: 下季 615±15 億；毛利率約 86.25% | F4: 文字 | G4: 財測 | H4: 1 | J4: 僅摘要 | K4: 46268 | L4: 46300 | M4: 公司預估，非實績 | N4: 下一季財報 | O4: https://news.cnyes.com/news/id/6619198
A5: =TEXT(ROW()-1,"C-000") -> C-004 | B5: AVGO | C5: 營收 | D5: FY26 Q3 | E5: 296 | F5: 億美元 | G5: 實績 | H5: 1 | J5: 已開原文 | K5: 46236 | L5: 46300 | M5: AI 半導體 167 億年增 221%；前五大終端客戶 55%、單一經銷商 50% | N5: 下一季財報 | O5: https://investors.broadcom.com/static-files/96641754-401f-4090-a4ab-210728c83a28
A6: =TEXT(ROW()-1,"C-000") -> C-005 | B6: AVGO | C6: 營收年增 | D6: FY26 Q3 | E6: 0.86 | F6: 比率 | G6: 實績 | H6: 1 | J6: 已開原文 | K6: 46236 | L6: 46300 | N6: 下一季財報 | O6: https://investors.broadcom.com/static-files/96641754-401f-4090-a4ab-210728c83a28
A7: =TEXT(ROW()-1,"C-000") -> C-006 | B7: AVGO | C7: 財測 | D7: FY26 Q3 | E7: Q4 營收約 348 億；AI 半導體 217 億 | F7: 文字 | G7: 財測 | H7: 1 | J7: 已開原文 | K7: 46236 | L7: 46300 | M7: 公司預估，非實績 | N7: 下一季財報 | O7: https://investors.broadcom.com/static-files/96641754-401f-4090-a4ab-210728c83a28
A8: =TEXT(ROW()-1,"C-000") -> C-007 | B8: MRVL | C8: 營收 | D8: FY27 Q2 | E8: 27.39 | F8: 億美元 | G8: 實績 | H8: 1 | J8: 僅摘要 | K8: 46235 | L8: 46300 | M8: 資料中心年增 46%；非 GAAP EPS 0.94、GAAP 0.33；毛利率為 GAAP | N8: 下一季財報 | O8: https://www.sec.gov/Archives/edgar/data/0001835632/000183563226000022/q227_8kx812026ex-991.htm
A9: =TEXT(ROW()-1,"C-000") -> C-008 | B9: MRVL | C9: 營收年增 | D9: FY27 Q2 | E9: 0.37 | F9: 比率 | G9: 實績 | H9: 1 | J9: 僅摘要 | K9: 46235 | L9: 46300 | N9: 下一季財報 | O9: https://www.sec.gov/Archives/edgar/data/0001835632/000183563226000022/q227_8kx812026ex-991.htm
A10: =TEXT(ROW()-1,"C-000") -> C-009 | B10: MRVL | C10: 財測 | D10: FY27 Q2 | E10: 投資人日 10/6 更新 | F10: 文字 | G10: 財測 | H10: 1 | J10: 僅摘要 | K10: 46235 | L10: 46300 | M10: 公司預估，非實績 | N10: 下一季財報 | O10: https://www.sec.gov/Archives/edgar/data/0001835632/000183563226000022/q227_8kx812026ex-991.htm
A11: =TEXT(ROW()-1,"C-000") -> C-010 | B11: LITE | C11: 營收 | D11: FY26 Q4 | E11: 10.063 | F11: 億美元 | G11: 實績 | H11: 1 | J11: 僅摘要 | K11: 46200 | L11: 46300 | M11: GAAP 淨損 72 億，來自可轉債轉換的一次性非現金損失；非 GAAP 毛利率 50.4% | N11: 下一季財報 | O11: https://investor.lumentum.com/financial-news-releases/news-details/2026/Lumentum-Announces-Fourth-Quarter-and-Full-Fiscal-Year-2026-Results/default.aspx
A12: =TEXT(ROW()-1,"C-000") -> C-011 | B12: LITE | C12: 營收年增 | D12: FY26 Q4 | E12: 1.093 | F12: 比率 | G12: 實績 | H12: 1 | J12: 僅摘要 | K12: 46200 | L12: 46300 | N12: 下一季財報 | O12: https://investor.lumentum.com/financial-news-releases/news-details/2026/Lumentum-Announces-Fourth-Quarter-and-Full-Fiscal-Year-2026-Results/default.aspx
A13: =TEXT(ROW()-1,"C-000") -> C-012 | B13: LITE | C13: 財測 | D13: FY26 Q4 | E13: 下季 12.25–12.75 億 | F13: 文字 | G13: 財測 | H13: 1 | J13: 僅摘要 | K13: 46200 | L13: 46300 | M13: 公司預估，非實績 | N13: 下一季財報 | O13: https://investor.lumentum.com/financial-news-releases/news-details/2026/Lumentum-Announces-Fourth-Quarter-and-Full-Fiscal-Year-2026-Results/default.aspx
A14: =TEXT(ROW()-1,"C-000") -> C-013 | B14: COHR | C14: 營收 | D14: FY26 Q4 | E14: 20.5 | F14: 億美元 | G14: 實績 | H14: 1 | J14: 僅摘要 | K14: 46203 | L14: 46300 | M14: 擬制年增 42%；非 GAAP 毛利率 40.2% | N14: 下一季財報 | O14: https://www.coherent.com/news/press-releases/fourth-quarter-and-fiscal-year-2026-results
A15: =TEXT(ROW()-1,"C-000") -> C-014 | B15: COHR | C15: 營收年增 | D15: FY26 Q4 | E15: 0.34 | F15: 比率 | G15: 實績 | H15: 1 | J15: 僅摘要 | K15: 46203 | L15: 46300 | N15: 下一季財報 | O15: https://www.coherent.com/news/press-releases/fourth-quarter-and-fiscal-year-2026-results
A16: =TEXT(ROW()-1,"C-000") -> C-015 | B16: ANET | C16: 營收 | D16: 2026 Q2 | E16: 30.36 | F16: 億美元 | G16: 實績 | H16: 1 | J16: 已開原文 | K16: 46203 | L16: 46300 | M16: 97 億不可取消採購承諾（94 億 12 個月內收貨）；未來將認列營收 84 億 | N16: 下一季財報 | O16: https://www.sec.gov/Archives/edgar/data/1596532/000159653226000175/anet-20260630.htm
A17: =TEXT(ROW()-1,"C-000") -> C-016 | B17: ANET | C17: 營收年增 | D17: 2026 Q2 | E17: 0.377 | F17: 比率 | G17: 實績 | H17: 1 | J17: 已開原文 | K17: 46203 | L17: 46300 | N17: 下一季財報 | O17: https://www.sec.gov/Archives/edgar/data/1596532/000159653226000175/anet-20260630.htm
A18: =TEXT(ROW()-1,"C-000") -> C-017 | B18: ANET | C18: 財測 | D18: 2026 Q2 | E18: 全年約 126 億（成長 40%）；Q3 約 33 億 | F18: 文字 | G18: 財測 | H18: 1 | J18: 已開原文 | K18: 46203 | L18: 46300 | M18: 公司預估，非實績 | N18: 下一季財報 | O18: https://www.sec.gov/Archives/edgar/data/1596532/000159653226000175/anet-20260630.htm
A19: =TEXT(ROW()-1,"C-000") -> C-018 | B19: VRT | C19: 營收 | D19: 2026 Q2 | E19: 32.74 | F19: 億美元 | G19: 實績 | H19: 1 | J19: 僅摘要 | K19: 46203 | L19: 46300 | M19: 歐非中東有機衰退 2%；併購貢獻 5 個百分點 | N19: 下一季財報 | O19: https://investors.vertiv.com/news/news-details/2026/Vertiv-Reports-Strong-Second-Quarter-2026-with-Diluted-EPS-Growth-of-53-Adjusted-Diluted-EPS-Growth-of-60-Raises-Full-Year-2026-Guidance-Across-All-Key-Metrics/default.aspx
A20: =TEXT(ROW()-1,"C-000") -> C-019 | B20: VRT | C20: 營收年增 | D20: 2026 Q2 | E20: 0.24 | F20: 比率 | G20: 實績 | H20: 1 | J20: 僅摘要 | K20: 46203 | L20: 46300 | N20: 下一季財報 | O20: https://investors.vertiv.com/news/news-details/2026/Vertiv-Reports-Strong-Second-Quarter-2026-with-Diluted-EPS-Growth-of-53-Adjusted-Diluted-EPS-Growth-of-60-Raises-Full-Year-2026-Guidance-Across-All-Key-Metrics/default.aspx
A21: =TEXT(ROW()-1,"C-000") -> C-020 | B21: VRT | C21: 財測 | D21: 2026 Q2 | E21: 全年有機成長 30–32% | F21: 文字 | G21: 財測 | H21: 1 | J21: 僅摘要 | K21: 46203 | L21: 46300 | M21: 公司預估，非實績 | N21: 下一季財報 | O21: https://investors.vertiv.com/news/news-details/2026/Vertiv-Reports-Strong-Second-Quarter-2026-with-Diluted-EPS-Growth-of-53-Adjusted-Diluted-EPS-Growth-of-60-Raises-Full-Year-2026-Guidance-Across-All-Key-Metrics/default.aspx
A22: =TEXT(ROW()-1,"C-000") -> C-021 | B22: ETN | C22: 營收 | D22: 2026 Q2 | E22: 85 | F22: 億美元 | G22: 實績 | H22: 1 | J22: 僅摘要 | K22: 46203 | L22: 46300 | M22: 訂單增 41% 是 12 個月滾動；美洲電氣利益率 29.5%→27.5% | N22: 下一季財報 | O22: https://www.businesswire.com/news/home/20260730561562/en/Eaton-Reports-Record-Second-Quarter-2026-Results-with-Strong-Organic-Growth-Accelerating-Orders-and-Backlog-and-Raises-Organic-Growth-Guidance
A23: =TEXT(ROW()-1,"C-000") -> C-022 | B23: ETN | C23: 營收年增 | D23: 2026 Q2 | E23: 0.21 | F23: 比率 | G23: 實績 | H23: 1 | J23: 僅摘要 | K23: 46203 | L23: 46300 | N23: 下一季財報 | O23: https://www.businesswire.com/news/home/20260730561562/en/Eaton-Reports-Record-Second-Quarter-2026-Results-with-Strong-Organic-Growth-Accelerating-Orders-and-Backlog-and-Raises-Organic-Growth-Guidance
A24: =TEXT(ROW()-1,"C-000") -> C-023 | B24: ETN | C24: 財測 | D24: 2026 Q2 | E24: 上修全年有機成長 | F24: 文字 | G24: 財測 | H24: 1 | J24: 僅摘要 | K24: 46203 | L24: 46300 | M24: 公司預估，非實績 | N24: 下一季財報 | O24: https://www.businesswire.com/news/home/20260730561562/en/Eaton-Reports-Record-Second-Quarter-2026-Results-with-Strong-Organic-Growth-Accelerating-Orders-and-Backlog-and-Raises-Organic-Growth-Guidance
A25: =TEXT(ROW()-1,"C-000") -> C-024 | B25: APH | C25: 營收 | D25: 2026 Q2 | E25: 87.58 | F25: 億美元 | G25: 實績 | H25: 1 | J25: 僅摘要 | K25: 46203 | L25: 46300 | M25: 併購貢獻 24 個百分點；訂單 107 億、訂單出貨比 1.23 | N25: 下一季財報 | O25: https://www.sec.gov/Archives/edgar/data/0000820313/000110465926087904/aph-20260729xex99d1.htm
A26: =TEXT(ROW()-1,"C-000") -> C-025 | B26: APH | C26: 營收年增 | D26: 2026 Q2 | E26: 0.55 | F26: 比率 | G26: 實績 | H26: 1 | J26: 僅摘要 | K26: 46203 | L26: 46300 | N26: 下一季財報 | O26: https://www.sec.gov/Archives/edgar/data/0000820313/000110465926087904/aph-20260729xex99d1.htm
A27: =TEXT(ROW()-1,"C-000") -> C-026 | B27: APH | C27: 財測 | D27: 2026 Q2 | E27: Q3 93–94 億 | F27: 文字 | G27: 財測 | H27: 1 | J27: 僅摘要 | K27: 46203 | L27: 46300 | M27: 公司預估，非實績 | N27: 下一季財報 | O27: https://www.sec.gov/Archives/edgar/data/0000820313/000110465926087904/aph-20260729xex99d1.htm
A28: =TEXT(ROW()-1,"C-000") -> C-027 | B28: 6857 | C28: 營收 | D28: FY26 Q1 | E28: 3675 | F28: 億日圓 | G28: 實績 | H28: 1 | J28: 僅摘要 | K28: 46203 | L28: 46300 | M28: 淨利含約 447 億日圓金融收益 | N28: 下一季財報 | O28: https://www.advantest.com/document/en/investors/ir-library/result/E_FR_FY2026_1Q.pdf
A29: =TEXT(ROW()-1,"C-000") -> C-028 | B29: 6857 | C29: 營收年增 | D29: FY26 Q1 | E29: 0.393 | F29: 比率 | G29: 實績 | H29: 1 | J29: 僅摘要 | K29: 46203 | L29: 46300 | N29: 下一季財報 | O29: https://www.advantest.com/document/en/investors/ir-library/result/E_FR_FY2026_1Q.pdf
A30: =TEXT(ROW()-1,"C-000") -> C-029 | B30: 6857 | C30: 財測 | D30: FY26 Q1 | E30: 全年營業利益 8,460 億日圓 | F30: 文字 | G30: 財測 | H30: 1 | J30: 僅摘要 | K30: 46203 | L30: 46300 | M30: 公司預估，非實績 | N30: 下一季財報 | O30: https://www.advantest.com/document/en/investors/ir-library/result/E_FR_FY2026_1Q.pdf
A31: =TEXT(ROW()-1,"C-000") -> C-030 | B31: PANW | C31: 營收 | D31: FY26 Q4 | E31: 34.1 | F31: 億美元 | G31: 實績 | H31: 1 | J31: 僅摘要 | K31: 46234 | L31: 46300 | M31: 當季 GAAP 淨損 2.82 億；成長含併購 | N31: 下一季財報 | O31: https://investors.paloaltonetworks.com/news-releases/news-release-details/palo-alto-networks-reports-fiscal-fourth-quarter-and-fiscal-10
A32: =TEXT(ROW()-1,"C-000") -> C-031 | B32: PANW | C32: 營收年增 | D32: FY26 Q4 | E32: 0.34 | F32: 比率 | G32: 實績 | H32: 1 | J32: 僅摘要 | K32: 46234 | L32: 46300 | N32: 下一季財報 | O32: https://investors.paloaltonetworks.com/news-releases/news-release-details/palo-alto-networks-reports-fiscal-fourth-quarter-and-fiscal-10
A33: =TEXT(ROW()-1,"C-000") -> C-032 | B33: PANW | C33: 財測 | D33: FY26 Q4 | E33: 新年度營收 141–142 億（成長 23–24%） | F33: 文字 | G33: 財測 | H33: 1 | J33: 僅摘要 | K33: 46234 | L33: 46300 | M33: 公司預估，非實績 | N33: 下一季財報 | O33: https://investors.paloaltonetworks.com/news-releases/news-release-details/palo-alto-networks-reports-fiscal-fourth-quarter-and-fiscal-10
A34: =TEXT(ROW()-1,"C-000") -> C-033 | B34: GEV | C34: 營收 | D34: 2026 Q2 | E34: 111 | F34: 億美元 | G34: 實績 | H34: 1 | J34: 僅摘要 | K34: 46203 | L34: 46300 | M34: 訂單 242 億有機增 88%；風電訂單有機衰退 40%；淨利率 5.8% | N34: 下一季財報 | O34: https://www.gevernova.com/sites/default/files/gev_webcast_pressrelease_07222026.pdf
A35: =TEXT(ROW()-1,"C-000") -> C-034 | B35: GEV | C35: 營收年增 | D35: 2026 Q2 | E35: 0.22 | F35: 比率 | G35: 實績 | H35: 1 | J35: 僅摘要 | K35: 46203 | L35: 46300 | N35: 下一季財報 | O35: https://www.gevernova.com/sites/default/files/gev_webcast_pressrelease_07222026.pdf
A36: =TEXT(ROW()-1,"C-000") -> C-035 | B36: GEV | C36: 財測 | D36: 2026 Q2 | E36: 上修全年財測 | F36: 文字 | G36: 財測 | H36: 1 | J36: 僅摘要 | K36: 46203 | L36: 46300 | M36: 公司預估，非實績 | N36: 下一季財報 | O36: https://www.gevernova.com/sites/default/files/gev_webcast_pressrelease_07222026.pdf
A37: =TEXT(ROW()-1,"C-000") -> C-036 | B37: 2330 | C37: 月營收 | D37: 2026-08 | E37: 5148.05 | F37: 億元 | G37: 實績 | H37: 4 | J37: 僅摘要 | K37: 46262 | L37: 46300 | M37: 公告日股價 2,450 元（快變） | N37: 每月 10 日 | O37: https://news.cnyes.com/news/id/6603050
A38: =TEXT(ROW()-1,"C-000") -> C-037 | B38: 2330 | C38: 月營收年增 | D38: 2026-08 | E38: 0.533 | F38: 比率 | G38: 實績 | H38: 4 | J38: 僅摘要 | K38: 46262 | L38: 46300 | N38: 每月 10 日 | O38: https://news.cnyes.com/news/id/6603050
A39: =TEXT(ROW()-1,"C-000") -> C-038 | B39: 2408 | C39: 月營收 | D39: 2026-08 | E39: 446.9 | F39: 億元 | G39: 實績 | H39: 4 | J39: 僅摘要 | K39: 46262 | L39: 46300 | M39: 新合約 7 月生效，月增停滯屬階梯式調價 | N39: 每月 10 日 | O39: https://news.ustv.com.tw/newsdetail/20260902A001020
A40: =TEXT(ROW()-1,"C-000") -> C-039 | B40: 2408 | C40: 月營收年增 | D40: 2026-08 | E40: 5.609 | F40: 比率 | G40: 實績 | H40: 4 | J40: 僅摘要 | K40: 46262 | L40: 46300 | N40: 每月 10 日 | O40: https://news.ustv.com.tw/newsdetail/20260902A001020
...

Sheet Risk_Factors
A1: 主觀評級，沒有量化依據。資料不足時填「未知」，不要填「低」。
A2: 公司 | B2: 雲端業者資本支出 | C2: 利率 | D2: 記憶體週期 | E2: 地緣與出口管制 | F2: 消費景氣 | G2: 評級把握度
A3: 台積電 | B3: 高 | C3: 中 | D3: 中 | E3: 高 | F3: 中 | G3: 低
A4: Broadcom | B4: 高 | C4: 高 | D4: 低 | E4: 中 | F4: 低 | G4: 低
A5: Marvell／Lumentum／Coherent | B5: 高 | C5: 高 | D5: 低 | E5: 中 | F5: 低 | G5: 低
A6: Arista／Vertiv | B6: 高 | C6: 中到高 | D6: 低 | E6: 未知 | F6: 低 | G6: 低
A7: 美光 | B7: 高 | C7: 高 | D7: 極高 | E7: 中 | F7: 中 | G7: 低
A8: 聯亞／台燿／奇鋐／雙鴻 | B8: 高 | C8: 高 | D8: 低 | E8: 中 | F8: 低 | G8: 低
A9: Eaton／GE Vernova | B9: 中 | C9: 中 | D9: 低 | E9: 未知 | F9: 低 | G9: 低
A10: 蘋果 | B10: 低到中 | C10: 中 | D10: 低 | E10: 高 | F10: 高 | G10: 低

Sheet Stress_Test
A1: 壓力測試：先算部位，再挑公司
A2: 黃格由你填寫。範例值 40%、槓桿 1 倍只是示範格式，請換成自己的數字。
A4: AI 相關部位佔可投資資金 | B4: 0.4
A5: 槓桿倍數（無融資填 1） | B5: 1
A6: 可接受的最大總資產跌幅
A8: 情境 | B8: 板塊假設跌幅 | C8: 總資產跌幅（公式） | D8: 是否超過可接受上限
A9: 溫和修正 | B9: 0.15 | C9: =$B$4*$B$5*B9 -> 0.06 | D9: =IF(ISNUMBER($B$6),IF(C9>$B$6,"超過","在範圍內"),"先填 B6") -> 先填 B6
A10: 估值修正 | B10: 0.3 | C10: =$B$4*$B$5*B10 -> 0.12 | D10: =IF(ISNUMBER($B$6),IF(C10>$B$6,"超過","在範圍內"),"先填 B6") -> 先填 B6
A11: 深度回檔 | B11: 0.5 | C11: =$B$4*$B$5*B11 -> 0.2 | D11: =IF(ISNUMBER($B$6),IF(C11>$B$6,"超過","在範圍內"),"先填 B6") -> 先填 B6

Sheet Predictions
A1: 說話者 | B1: 說話時間 | C1: 預測內容 | D1: 類型 | E1: 實際結果 | F1: 評分 | G1: 誤差（公式） | H1: 備註
A2: Emmy | B2: 9 月上旬 | C2: 8 月 CPI 應該不會爆 | D2: 方向 | E2: 偏熱 | F2: 錯 | H2: 影片確切日期待補
A3: Emmy | B3: 9 月上旬與中旬 | C3: 9 月不太可能升息 | D3: 方向 | E3: 12:0 升息一碼 | F3: 錯 | H3: 連講兩週
A4: Emmy | B4: 9 月下旬 | C4: 美光營收 575–630 億美元 | D4: 數值區間 | E4: 542.3 億 | F4: 數字未中；方向對 | G4: =542.3/575-1 -> -0.056869565 | H4: 相對區間下限
A5: Emmy | B5: 9 月下旬 | C5: 美光財測是懸念、股價不會大漲 | D5: 方向 | E5: 盤後近乎收平 | F5: 對
A6: Emmy | B6: 9 月上旬 | C6: 9 月下旬有作帳行情 | D6: 未定義 | E6: — | F6: 無法評分 | H6: 事前沒有定義標準
A7: Emmy | B7: 9 月中旬 | C7: 年底前再升息半碼 | D7: 數值 | E7: 點陣圖為再升一碼 | F7: 口誤
A8: Emmy | B8: 9 月中旬 | C8: SENKO 日股代號 9069 | D8: 事實 | E8: 兩家無關 | F8: 錯 | H8: 實體對錯
A9: Emmy | B9: 9 月下旬 | C9: Meta AI 營收 100–150 億美元 | D9: 數值區間 | E9: 待 10/28 財報 | F9: 未揭曉 | H9: 估算方法不成立

Sheet Change_Log
A1: 編號 | B1: 原本 | C1: 改為 | D1: 對結論的影響 | E1: 依據
A2: 20261005-01 | B2: Broadcom 前五大客戶 55% 未查到 | C2: 已確認 55%，另有經銷商 50% | D2: 中 | E2: https://investors.broadcom.com/static-files/96641754-401f-4090-a4ab-210728c83a28
A3: 20261005-02 | B3: Arista 採購承諾 97 億 | C3: 註明是對供應商的承諾 | D3: 高 | E3: https://www.sec.gov/Archives/edgar/data/1596532/000159653226000175/anet-20260630.htm
A4: 20261005-03 | B4: Dots 開放 Enterprise | C4: Enterprise 為測試版、預設關閉 | D4: 低 | E4: https://openai.com/index/introducing-dots/
A5: 20261005-04 | B5: Muse 22 天 500 萬下載 | C5: 註明為 Sensor Tower 估計 | D5: 低 | E5: https://www.forbes.com/sites/maryroeloffs/2026/09/30/metas-muse-ai-assistant-hits-5-million-downloads-outpacing-growth-of-chatgpt-grok-and-claude/
A6: 20261005-05 | B6: 流程七步、三類說法 | C6: 八步、六種標籤 | D6: 低
A7: 20261005-06 | B7: Dots 的 Edu 與 Healthcare 未查證 | C7: 已確認 | D7: 低 | E7: https://openai.com/index/introducing-dots/
A8: 20261005-07 | B8: 磷化銅 | C8: 磷化銦（InP） | D8: 中
A9: 20261005-08 | B9: 訂單出貨比大於 1 代表需求大於供給 | C9: 只代表接單快於出貨 | D9: 中
A10: 20261005-09 | B10: 在手訂單與剩餘履約義務合為一詞 | C10: 拆成三個詞 | D10: 中
A11: 20261005-10 | B11: 任一家雲端業者下修即轉壞 | C11: 一家黃燈、多家或合計下修才紅燈 | D11: 中
A12: 20261005-11 | B12: 好消息加股價跌等於預期過滿 | C12: 需扣掉同類指數，且仍屬推論 | D12: 中
A13: 20261005-12 | B13: Arista 承諾「一年內到期」 | C13: 「預計 12 個月內收貨」，並補 84 億未來營收 | D13: 中 | E13: https://www.sec.gov/Archives/edgar/data/1596532/000159653226000175/anet-20260630.htm
A14: 20261005-13 | B14: Event_Log 超額漲跌公式放在 H 欄（自我參照），I 欄空白 | C14: 公式移到 I 欄，H 欄恢復為手填的同類指數漲跌 | D14: 高（原本算不出超額漲跌） | E14: Codex 審查報告 2026-10-05
